I'm sorry, but an uncaught exception occurred.

While running game code:
  File "game/xenia.rpy", line 168, in script
    x "Right here."
IOError: Couldn't find file 'audio/xeniadate2.mp3'.

-- Full Traceback ------------------------------------------------------------

Full traceback:
  File "game/xenia.rpy", line 168, in script
    x "Right here."
  File "/home/cero/renpy-7.3.5-sdk/renpy/ast.py", line 708, in execute
    renpy.exports.say(who, what, *args, **kwargs)
  File "/home/cero/renpy-7.3.5-sdk/renpy/exports.py", line 1345, in say
    who(what, *args, **kwargs)
  File "/home/cero/renpy-7.3.5-sdk/renpy/character.py", line 1142, in __call__
    self.do_display(who, what, cb_args=self.cb_args, **display_args)
  File "/home/cero/renpy-7.3.5-sdk/renpy/character.py", line 842, in do_display
    **display_args)
  File "/home/cero/renpy-7.3.5-sdk/renpy/character.py", line 591, in display_say
    rv = renpy.ui.interact(mouse='say', type=type, roll_forward=roll_forward)
  File "/home/cero/renpy-7.3.5-sdk/renpy/ui.py", line 297, in interact
    rv = renpy.game.interface.interact(roll_forward=roll_forward, **kwargs)
  File "/home/cero/renpy-7.3.5-sdk/renpy/display/core.py", line 2702, in interact
    repeat, rv = self.interact_core(preloads=preloads, trans_pause=trans_pause, **kwargs)
  File "/home/cero/renpy-7.3.5-sdk/renpy/display/core.py", line 3380, in interact_core
    renpy.audio.audio.periodic()
  File "/home/cero/renpy-7.3.5-sdk/renpy/audio/audio.py", line 1060, in periodic
    six.reraise(exc[0], exc[1], exc[2])
  File "/home/cero/renpy-7.3.5-sdk/renpy/audio/audio.py", line 1038, in periodic_thread_main
    periodic_pass()
  File "/home/cero/renpy-7.3.5-sdk/renpy/audio/audio.py", line 979, in periodic_pass
    c.periodic()
  File "/home/cero/renpy-7.3.5-sdk/renpy/audio/audio.py", line 457, in periodic
    topf = load(self.file_prefix + filename + self.file_suffix)
  File "/home/cero/renpy-7.3.5-sdk/renpy/audio/audio.py", line 73, in load
    rv = renpy.loader.load(fn)
  File "/home/cero/renpy-7.3.5-sdk/renpy/loader.py", line 576, in load
    raise IOError("Couldn't find file '%s'." % name)
IOError: Couldn't find file 'audio/xeniadate2.mp3'.

Linux-4.13.0-32-generic-x86_64-with-debian-stretch-sid
Ren'Py 7.3.5.606
WTHC 1.0
Sat Jul  4 14:14:01 2020
